[2025-02-25T15:24:19.025+0000] {taskinstance.py:1956} INFO - Dependencies all met for dep_context=non-requeueable deps ti=<TaskInstance: dvc_pipeline.train_model manual__2025-02-25T15:22:00.937503+00:00 [queued]>
[2025-02-25T15:24:19.062+0000] {taskinstance.py:1956} INFO - Dependencies all met for dep_context=requeueable deps ti=<TaskInstance: dvc_pipeline.train_model manual__2025-02-25T15:22:00.937503+00:00 [queued]>
[2025-02-25T15:24:19.064+0000] {taskinstance.py:2170} INFO - Starting attempt 1 of 1
[2025-02-25T15:24:19.249+0000] {taskinstance.py:2191} INFO - Executing <Task(PythonOperator): train_model> on 2025-02-25 15:22:00.937503+00:00
[2025-02-25T15:24:19.280+0000] {standard_task_runner.py:60} INFO - Started process 180 to run task
[2025-02-25T15:24:19.288+0000] {standard_task_runner.py:87} INFO - Running: ['***', 'tasks', 'run', 'dvc_pipeline', 'train_model', 'manual__2025-02-25T15:22:00.937503+00:00', '--job-id', '95', '--raw', '--subdir', 'DAGS_FOLDER/weather_pipeline_dag.py', '--cfg-path', '/tmp/tmpl8fpfktr']
[2025-02-25T15:24:19.296+0000] {standard_task_runner.py:88} INFO - Job 95: Subtask train_model
[2025-02-25T15:24:19.388+0000] {warnings.py:109} WARNING - /home/***/.local/lib/python3.8/site-packages/***/settings.py:194: DeprecationWarning: The sql_alchemy_conn option in [core] has been moved to the sql_alchemy_conn option in [database] - the old setting has been used, but please update your config.
  SQL_ALCHEMY_CONN = conf.get("database", "SQL_ALCHEMY_CONN")

[2025-02-25T15:24:19.497+0000] {task_command.py:423} INFO - Running <TaskInstance: dvc_pipeline.train_model manual__2025-02-25T15:22:00.937503+00:00 [running]> on host e4b564b54e23
[2025-02-25T15:24:19.772+0000] {taskinstance.py:2480} INFO - Exporting env vars: AIRFLOW_CTX_DAG_OWNER='***' AIRFLOW_CTX_DAG_ID='dvc_pipeline' AIRFLOW_CTX_TASK_ID='train_model' AIRFLOW_CTX_EXECUTION_DATE='2025-02-25T15:22:00.937503+00:00' AIRFLOW_CTX_TRY_NUMBER='1' AIRFLOW_CTX_DAG_RUN_ID='manual__2025-02-25T15:22:00.937503+00:00'
[2025-02-25T15:24:27.670+0000] {logging_mixin.py:188} INFO - Error occurred while running command: Command 'python /opt/***/src/models/train_model.py' returned non-zero exit status 1.
[2025-02-25T15:24:27.672+0000] {taskinstance.py:2698} ERROR - Task failed with exception
Traceback (most recent call last):
  File "/home/airflow/.local/lib/python3.8/site-packages/airflow/models/taskinstance.py", line 433, in _execute_task
    result = execute_callable(context=context, **execute_callable_kwargs)
  File "/home/airflow/.local/lib/python3.8/site-packages/airflow/operators/python.py", line 199, in execute
    return_value = self.execute_callable()
  File "/home/airflow/.local/lib/python3.8/site-packages/airflow/operators/python.py", line 216, in execute_callable
    return self.python_callable(*self.op_args, **self.op_kwargs)
  File "/opt/airflow/dags/weather_pipeline_dag.py", line 9, in run_command
    subprocess.check_call(command, shell=True)
  File "/usr/local/lib/python3.8/subprocess.py", line 364, in check_call
    raise CalledProcessError(retcode, cmd)
subprocess.CalledProcessError: Command 'python /opt/airflow/src/models/train_model.py' returned non-zero exit status 1.
[2025-02-25T15:24:27.690+0000] {taskinstance.py:1138} INFO - Marking task as FAILED. dag_id=dvc_pipeline, task_id=train_model, execution_date=20250225T152200, start_date=20250225T152419, end_date=20250225T152427
[2025-02-25T15:24:27.711+0000] {standard_task_runner.py:107} ERROR - Failed to execute job 95 for task train_model (Command 'python /opt/airflow/src/models/train_model.py' returned non-zero exit status 1.; 180)
[2025-02-25T15:24:27.726+0000] {local_task_job_runner.py:234} INFO - Task exited with return code 1
[2025-02-25T15:24:27.752+0000] {taskinstance.py:3280} INFO - 0 downstream tasks scheduled from follow-on schedule check
