[2025-02-25T01:28:58.785+0000] {taskinstance.py:1956} INFO - Dependencies all met for dep_context=non-requeueable deps ti=<TaskInstance: dvc_pipeline.evaluate_model manual__2025-02-25T01:26:11.635563+00:00 [queued]>
[2025-02-25T01:28:58.812+0000] {taskinstance.py:1956} INFO - Dependencies all met for dep_context=requeueable deps ti=<TaskInstance: dvc_pipeline.evaluate_model manual__2025-02-25T01:26:11.635563+00:00 [queued]>
[2025-02-25T01:28:58.815+0000] {taskinstance.py:2170} INFO - Starting attempt 1 of 1
[2025-02-25T01:28:58.852+0000] {taskinstance.py:2191} INFO - Executing <Task(PythonOperator): evaluate_model> on 2025-02-25 01:26:11.635563+00:00
[2025-02-25T01:28:58.866+0000] {standard_task_runner.py:60} INFO - Started process 195 to run task
[2025-02-25T01:28:58.878+0000] {standard_task_runner.py:87} INFO - Running: ['***', 'tasks', 'run', 'dvc_pipeline', 'evaluate_model', 'manual__2025-02-25T01:26:11.635563+00:00', '--job-id', '77', '--raw', '--subdir', 'DAGS_FOLDER/weather_pipeline_dag.py', '--cfg-path', '/tmp/tmpliv8db0_']
[2025-02-25T01:28:58.883+0000] {standard_task_runner.py:88} INFO - Job 77: Subtask evaluate_model
[2025-02-25T01:28:58.909+0000] {warnings.py:109} WARNING - /home/***/.local/lib/python3.8/site-packages/***/settings.py:194: DeprecationWarning: The sql_alchemy_conn option in [core] has been moved to the sql_alchemy_conn option in [database] - the old setting has been used, but please update your config.
  SQL_ALCHEMY_CONN = conf.get("database", "SQL_ALCHEMY_CONN")

[2025-02-25T01:28:58.997+0000] {task_command.py:423} INFO - Running <TaskInstance: dvc_pipeline.evaluate_model manual__2025-02-25T01:26:11.635563+00:00 [running]> on host 7efe327aec71
[2025-02-25T01:28:59.168+0000] {taskinstance.py:2480} INFO - Exporting env vars: AIRFLOW_CTX_DAG_OWNER='***' AIRFLOW_CTX_DAG_ID='dvc_pipeline' AIRFLOW_CTX_TASK_ID='evaluate_model' AIRFLOW_CTX_EXECUTION_DATE='2025-02-25T01:26:11.635563+00:00' AIRFLOW_CTX_TRY_NUMBER='1' AIRFLOW_CTX_DAG_RUN_ID='manual__2025-02-25T01:26:11.635563+00:00'
[2025-02-25T01:29:05.004+0000] {logging_mixin.py:188} INFO - Error occurred while running command: Command 'python /opt/***/src/models/evaluate_model.py' returned non-zero exit status 1.
[2025-02-25T01:29:05.006+0000] {taskinstance.py:2698} ERROR - Task failed with exception
Traceback (most recent call last):
  File "/home/airflow/.local/lib/python3.8/site-packages/airflow/models/taskinstance.py", line 433, in _execute_task
    result = execute_callable(context=context, **execute_callable_kwargs)
  File "/home/airflow/.local/lib/python3.8/site-packages/airflow/operators/python.py", line 199, in execute
    return_value = self.execute_callable()
  File "/home/airflow/.local/lib/python3.8/site-packages/airflow/operators/python.py", line 216, in execute_callable
    return self.python_callable(*self.op_args, **self.op_kwargs)
  File "/opt/airflow/dags/weather_pipeline_dag.py", line 9, in run_command
    subprocess.check_call(command, shell=True)
  File "/usr/local/lib/python3.8/subprocess.py", line 364, in check_call
    raise CalledProcessError(retcode, cmd)
subprocess.CalledProcessError: Command 'python /opt/airflow/src/models/evaluate_model.py' returned non-zero exit status 1.
[2025-02-25T01:29:05.028+0000] {taskinstance.py:1138} INFO - Marking task as FAILED. dag_id=dvc_pipeline, task_id=evaluate_model, execution_date=20250225T012611, start_date=20250225T012858, end_date=20250225T012905
[2025-02-25T01:29:05.048+0000] {standard_task_runner.py:107} ERROR - Failed to execute job 77 for task evaluate_model (Command 'python /opt/airflow/src/models/evaluate_model.py' returned non-zero exit status 1.; 195)
[2025-02-25T01:29:05.085+0000] {local_task_job_runner.py:234} INFO - Task exited with return code 1
[2025-02-25T01:29:05.112+0000] {taskinstance.py:3280} INFO - 0 downstream tasks scheduled from follow-on schedule check
